OUTPUT:


ERROR:
Traceback (most recent call last):
  File "/home/ethan/repository/backup/LLM_Routing/llm/extra_info/verifier/single/GTSP/15/city_15_instance_3/0/0/verifier_r1_v2.py", line 56, in <module>
    result = test_tour_solution(proposed_tour, proposed_cost, city_coordinates, city_groups)
             ^^^^^^^^^^^^^^^^^^^^^^^^^^^^^^^^^^^^^^^^^^^^^^^^^^^^^^^^^^^^^^^^^^^^^^^^^^^^^^^
  File "/home/ethan/repository/backup/LLM_Routing/llm/extra_info/verifier/single/GTSP/15/city_15_instance_3/0/0/verifier_r1_v2.py", line 22, in test_tour_solution
    found_group_indices.add(group_multiple)
                            ^^^^^^^^^^^^^^
NameError: name 'group_multiple' is not defined


