OUTPUT:


ERROR:
Traceback (most recent call last):
  File "/home/ethan/repository/backup/LLM_Routing/llm/extra_info/verifier/single/BTSP/15/city_15_instance_2/3/2/verifier_r1_v1.py", line 55, in <module>
    print(test_solution())
          ^^^^^^^^^^^^^^^
  File "/home/ethan/repository/backup/LLM_Routing/llm/extra_info/verifier/single/BTSP/15/city_15_instance_2/3/2/verifier_r1_v1.py", line 48, in test_solution
    if not math.isclose(max_distance, reported_max_value, rel_tol=1e-5):
                                      ^^^^^^^^^^^^^^^^^^
NameError: name 'reported_max_value' is not defined. Did you mean: 'reported_max_distance'?


