OUTPUT:


ERROR:
Traceback (most recent call last):
  File "/home/ethan/repository/few-shot/LLM_Routing/llm/extra_info_math/solution/multiple/CVRP/10/P-n16-k8/3/0/solution_r0.py", line 82, in <module>
    main()
  File "/home/ethan/repository/few-shot/LLM_Routing/llm/extra_info_math/solution/multiple/CVRP/10/P-n16-k8/3/0/solution_r0.py", line 30, in main
    data = create_data_model()
           ^^^^^^^^^^^^^^^^^^^
  File "/home/ethan/repository/few-shot/LLM_Routing/llm/extra_info_math/solution/multiple/CVRP/10/P-n16-k8/3/0/solution_r0.py", line 23, in create_data_model
    distances[from_counter][to_attribute_counter] = 0
                            ^^^^^^^^^^^^^^^^^^^^
NameError: name 'to_attribute_counter' is not defined


